Workbook

Sheet Summary
B2: Participant Name
A4: 1 | B4: Kylian Mbappé | C4: FRA | D4: 2 | E4: Harry Kane | F4: ENG | G4: 3 | H4: Florian Wirtz | I4: GER | K4: goal, assists | L4: 1 point
B5: Matheus Cunha | C5: BRA | E5: Vinícius Júnior | F5: BRA | H5: Erling Haaland | I5: NOR | K5: game winner | L5: 1 point
B6: Lionel Messi | C6: ARG | E6: Cristiano Ronaldo | F6: POR | H6: Kevin De Bruyne | I6: BEL | K6: goalie win | L6: 1 point
B7: Julián Álvarez | C7: ARG | E7: Kai Havertz | F7: GER | H7: Darwin Núñez | I7: URG | K7: goalie clean sheet | L7: 1 points
B8: Memphis Depay | C8: NET | E8: Lamine Yamal | F8: SPN | H8: Breel Embolo | I8: SWZ | K8: goalie saves | L8: 0.2 points
B9: Jamal Musiala | C9: GER | E9: Marcus Thuram | F9: FRA | H9: Marko Arnautovic | I9: AUT | K9: goalie goals conceeded | L9: -0.25
A11: 4 | B11: Ousmane Dembélé | C11: FRA | D11: 5 | E11: Bukayo Saka | F11: ENG | G11: 6 | H11: Ismael Saibari | I11: MOR | K11: 1 minute played (0.75 per 90) | L11: 0.0083
B12: Romelu Lukaku | C12: BEL | E12: Charles De Ketelaer | F12: BEL | H12: Weston McKennie | I12: USA | K12: Yellow Card | L12: -0.25
B13: Raphinha | C13: BRA | E13: Luis Díaz | F13: COL | H13: Viktor Gyökeres | I13: SWE | K13: Red Card | L13: -0.5
B14: Patrik Schick | C14: CZE | E14: Federico Valverde | F14: URG | H14: Edin Dzeko | I14: BOS
B15: Cody Gakpo | C15: NET | E15: Endrick | F15: BRA | H15: Donyell Malen | I15: NET | K15: 1) Pick one player from each bracket
B16: Andrej Kramaric | C16: CRO | E16: Mikel Oyarzabal | F16: SPN | H16: Rodri | I16: SPN | K16: 2) Bottom four are goalkeepers
A18: 7 | B18: Aleksandar Pavlović | C18: GER | D18: 8 | E18: Alexis Mac Allister | F18: ARG | G18: 9 | H18: Mohamed Salah | I18: EGY | K18: 3) Choose Wisely:
B19: Brahim Díaz | C19: MOR | E19: Marcel Sabitzer | F19: AUT | H19: Son Heung-min | I19: KOR | K19: WORLD CUP WINNER: Will get 3 points (as they have advance to the semi finals, advanced to the finals, and won the trophy
B20: Inaki Williams | C20: GHA | E20: Jonathan David | F20: CAN | H20: Casemiro | I20: BRA | K20: WORLD CUP FINALIST: Will get max 2 points (advance to semi final, advance to finals - you will not be eligible for the Winner points as you did not select them
B21: Bruno Fernandes | C21: POR | E21: Enner Valencia | F21: ECU | H21: Arda Güler | I21: TUR | K21: ADVANCE TO SEMI FINAL: Will be awarded max 1 points if your team makes the semi final (will not be awarded points for advancing to final, nor lifting the trophy)
B22: Aurélien Tchouaméni | C22: FRA | E22: Leroy Sané | F22: GER | H22: Antoine Semenyo | I22: GHA
B23: Jérémy Doku | C23: BEL | E23: Alexander Isak | F23: SWE | H23: Ayase Ueda | I23: JPN | K23: 4) Send to picklessean@gmail.com, as well as $40 to pariticipate
A25: 10 | B25: Moisés Caicedo | C25: ECU | D25: 11 | E25: Frenkie de Jong | F25: NET | G25: 12 | H25: Nico Williams | I25: SPN
B26: Enzo Fernández | C26: ARG | E26: James Rodríguez | F26: COL | H26: Raúl Jiménez | I26: MEX
B27: Omar Marmoush | C27: EGY | E27: Michael Olise | F27: FRA | H27: Folarin Balogun | I27: USA
B28: Jude Bellingham | C28: ENG | E28: Kenan Yıldız | F28: TUR | H28: Marcus Rashford | I28: ENG
B29: Neymar Jr | C29: BRA | E29: Lautaro Martínez | F29: ARG | H29: Franck Kessié | I29: CIV | L29: Please fill out the below
B30: Tomáš Souček | C30: CZE | E30: Declan Rice | F30: ENG | H30: Thiago Almada | I30: ARG | L30: 1 | M30: Lionel Messi
L31: 2 | M31: Harry Kane
A32: 13 | B32: Jordan Ayew | C32: GHA | D32: 14 | E32: Elyes Skhiri | F32: TUN | G32: 15 | H32: Tajon Buchanan | I32: CAN | L32: 3 | M32: Erling Haaland
B33: Riyad Mahrez | C33: ALG | E33: Vitinha | F33: POR | H33: Rayan Cherki | I33: FRA | L33: 4 | M33: Romelu Lukaku
B34: Sadio Mané | C34: SEN | E34: Christian Pulisic | F34: USA | H34: Nico Paz | I34: ARG | L34: 5 | M34: Bukayo Saka
B35: Granit Xhaka | C35: SWZ | E35: Yan Diomandé | F35: CIV | H35: Nicolas Jackson | I35: SEN | L35: 6 | M35: Ismael Saibari
B36: Luka Modrić | C36: CRO | E36: Amadou Onana | F36: BEL | H36: Amine Gouiri | I36: ALG | L36: 7 | M36: Bruno Fernandes
B37: Martin Ødegaard | C37: NOR | E37: Antonio Nusa | F37: NOR | H37: Diego Gómez | I37: PAR | L37: 8 | M37: Marcel Sabitzer
L38: 9 | M38: Arda Güler
A39: 16 | B39: Eldor Shomurodov | C39: UZK | D39: 17 | E39: Themba Zwane | F39: RSA | G39: 18 | H39: Hakan Çalhanoğlu | I39: TUR | L39: 10 | M39: Jude Bellingham
B40: Firas Al-Buraikan | C40: SAU | E40: Frantzdy Pierrot | F40: HAI | H40: Ferran Torres | I40: SPN | L40: 11 | M40: Kenan Yıldız
B41: Chris Wood | C41: NZD | E41: Jackson Irvine | F41: AUS | H41: João Neves | I41: POR | L41: 12 | M41: Folarin Balogun
B42: Yoane Wissa | C42: CON | E42: antonio sanabria | F42: PAR | H42: Konrad Laimer | I42: AUT | L42: 13 | M42: Sadio Mané
B43: Ryan Mendes | C43: CPV | E43: Lawrence Shankland | F43: SCO | H43: Antonee Robinson | I43: USA | L43: 14 | M43: Antonio Nusa
B44: Mehdi Taremi | C44: IRAN | E44: Almoez Ali | F44: QAT | H44: Ivan Perisic | I44: CRO | L44: 15 | M44: Nico Paz
L45: 16 | M45: Firas Al-Buraikan
...

Sheet NEW DISPLAY
R1: Mins played
R2: YC | AJ2: https://theleaguetables.com/moes-tavern-wc-pool
R3: RD
B4: Participant | C4: Players | D4: Country | F4: Minutes Played | G4: Goals | H4: Assist | I4: Game Winning Goals | J4: Yellow Cards | K4: Red Cards | L4: Wins | M4: Clean sheet | N4: Saves | O4: Goals Conceded | P4: Total Points | R4: Saves | AB4: Rank | AC4: Name | AD4: Points
B5: Sean Pickles | F5: =SUM(F6:F35) -> 11723 | G5: =SUM(G6:G35) -> 42 | H5: =SUM(H6:H35) -> 22 | I5: =SUM(I6:I35) -> 16 | J5: =SUM(J6:J35) -> 7 | K5: =SUM(K6:K35) -> 0 | L5: =SUM(L6:L35) -> 20 | M5: =SUM(M6:M35) -> 12 | ... P5: =SUM(P6:P35) -> 212.3509 | S5: Sean Pickles | T5: =RANK(X5,$X$5:$X$45) -> 3 | U5: Sean Pickles | V5: =VLOOKUP(U5,$B$4:$P$1245,15,FALSE) -> 212.3509 | W5: 1e-08 | X5: =V5+W5 -> 212.3509 | AB5: 1 | AC5: =VLOOKUP(AB5,$T$5:$V$45,2,FALSE) -> Bob Reynolds | AD5: =VLOOKUP(AB5,$T$5:$V$45,3,FALSE) -> 214.2248
C6: Lionel Messi | D6: =IFERROR(VLOOKUP($C6,'World Cup Players'!B:X,3,FALSE),0) -> ar Argentina | F6: =IFERROR(VLOOKUP($C6,'World Cup Players'!B:X,9,FALSE),0) -> 620 | G6: =IFERROR(VLOOKUP($C6,'World Cup Players'!B:X,11,FALSE),0) -> 8 | H6: =IFERROR(VLOOKUP($C6,'World Cup Players'!B:X,12,FALSE),0) -> 4 | I6: =IFERROR(VLOOKUP($C6,'GAME WINNING GOALS'!A:B,2,FALSE),0) -> 2 | J6: =IFERROR(VLOOKUP($C6,'World Cup Players'!B:X,17,FALSE),0) -> 0 | K6: =IFERROR(VLOOKUP($C6,'World Cup Players'!B:X,18,FALSE),0) -> 0 | L6: =IFERROR(VLOOKUP($C6,'World Cup GK'!B:AE,16,FALSE),0) -> 0 | M6: =IFERROR(VLOOKUP($C6,'World Cup GK'!B:AE,19,FALSE),0) -> 0 | N6: =IFERROR(VLOOKUP($C6,'World Cup GK'!B:AE,14,FALSE),0) -> 0 | O6: =IFERROR(VLOOKUP($C6,'World Cup GK'!B:AE,11,FALSE),0) -> 0 | P6: =SUM((F6*0.0083)+G6+H6+I6+L6+M6+(N6*0.2))-((J6*0.25)+(K6*0.5))-(O6*0.25) -> 19.146 | S6: Eleni Mastoras | T6: =RANK(X6,$X$5:$X$45) -> 35 | U6: Eleni Mastoras | V6: =VLOOKUP(U6,$B$4:$P$1245,15,FALSE) -> 168.7195 | W6: =0.000000001+W5 -> 1.1e-08 | X6: =V6+W6 -> 168.7195 | AB6: 2 | AC6: =VLOOKUP(AB6,$T$5:$V$45,2,FALSE) -> Thayer Algor | AD6: =VLOOKUP(AB6,$T$5:$V$45,3,FALSE) -> 214.0375
C7: Harry Kane | D7: =IFERROR(VLOOKUP($C7,'World Cup Players'!B:X,3,FALSE),0) -> eng England | F7: =IFERROR(VLOOKUP($C7,'World Cup Players'!B:X,9,FALSE),0) -> 652 | G7: =IFERROR(VLOOKUP($C7,'World Cup Players'!B:X,11,FALSE),0) -> 6 | H7: =IFERROR(VLOOKUP($C7,'World Cup Players'!B:X,12,FALSE),0) -> 1 | I7: =IFERROR(VLOOKUP($C7,'GAME WINNING GOALS'!A:B,2,FALSE),0) -> 2 | J7: =IFERROR(VLOOKUP($C7,'World Cup Players'!B:X,17,FALSE),0) -> 0 | K7: =IFERROR(VLOOKUP($C7,'World Cup Players'!B:X,18,FALSE),0) -> 0 | L7: =IFERROR(VLOOKUP($C7,'World Cup GK'!B:AE,16,FALSE),0) -> 0 | M7: =IFERROR(VLOOKUP($C7,'World Cup GK'!B:AE,19,FALSE),0) -> 0 | N7: =IFERROR(VLOOKUP($C7,'World Cup GK'!B:AE,14,FALSE),0) -> 0 | O7: =IFERROR(VLOOKUP($C7,'World Cup GK'!B:AE,11,FALSE),0) -> 0 | P7: =SUM((F7*0.0083)+G7+H7+I7+L7+M7+(N7*0.2))-((J7*0.25)+(K7*0.5))-(O7*0.25) -> 14.4116 | S7: Kevin Pickles | T7: =RANK(X7,$X$5:$X$45) -> 20 | U7: Kevin Pickles | V7: =VLOOKUP(U7,$B$4:$P$1245,15,FALSE) -> 187.659 | W7: =0.000000001+W6 -> 1.2e-08 | X7: =V7+W7 -> 187.659 | AB7: 3 | AC7: =VLOOKUP(AB7,$T$5:$V$45,2,FALSE) -> Sean Pickles | AD7: =VLOOKUP(AB7,$T$5:$V$45,3,FALSE) -> 212.3509
C8: Erling Haaland | D8: =IFERROR(VLOOKUP($C8,'World Cup Players'!B:X,3,FALSE),0) -> no Norway | F8: =IFERROR(VLOOKUP($C8,'World Cup Players'!B:X,9,FALSE),0) -> 465 | G8: =IFERROR(VLOOKUP($C8,'World Cup Players'!B:X,11,FALSE),0) -> 7 | H8: =IFERROR(VLOOKUP($C8,'World Cup Players'!B:X,12,FALSE),0) -> 0 | I8: =IFERROR(VLOOKUP($C8,'GAME WINNING GOALS'!A:B,2,FALSE),0) -> 4 | J8: =IFERROR(VLOOKUP($C8,'World Cup Players'!B:X,17,FALSE),0) -> 0 | K8: =IFERROR(VLOOKUP($C8,'World Cup Players'!B:X,18,FALSE),0) -> 0 | L8: =IFERROR(VLOOKUP($C8,'World Cup GK'!B:AE,16,FALSE),0) -> 0 | M8: =IFERROR(VLOOKUP($C8,'World Cup GK'!B:AE,19,FALSE),0) -> 0 | N8: =IFERROR(VLOOKUP($C8,'World Cup GK'!B:AE,14,FALSE),0) -> 0 | O8: =IFERROR(VLOOKUP($C8,'World Cup GK'!B:AE,11,FALSE),0) -> 0 | P8: =SUM((F8*0.0083)+G8+H8+I8+L8+M8+(N8*0.2))-((J8*0.25)+(K8*0.5))-(O8*0.25) -> 14.8595 | S8: Tom Mullrooney | T8: =RANK(X8,$X$5:$X$45) -> 31 | U8: Tom Mullrooney | V8: =VLOOKUP(U8,$B$4:$P$1245,15,FALSE) -> 173.0693 | W8: =0.000000001+W7 -> 1.3e-08 | X8: =V8+W8 -> 173.0693 | AB8: 4 | AC8: =VLOOKUP(AB8,$T$5:$V$45,2,FALSE) -> Brian Ihnacak | AD8: =VLOOKUP(AB8,$T$5:$V$45,3,FALSE) -> 208.8653
C9: Romelu Lukaku | D9: =IFERROR(VLOOKUP($C9,'World Cup Players'!B:X,3,FALSE),0) -> be Belgium | F9: =IFERROR(VLOOKUP($C9,'World Cup Players'!B:X,9,FALSE),0) -> 233 | G9: =IFERROR(VLOOKUP($C9,'World Cup Players'!B:X,11,FALSE),0) -> 3 | H9: =IFERROR(VLOOKUP($C9,'World Cup Players'!B:X,12,FALSE),0) -> 1 | I9: =IFERROR(VLOOKUP($C9,'GAME WINNING GOALS'!A:B,2,FALSE),0) -> 0 | J9: =IFERROR(VLOOKUP($C9,'World Cup Players'!B:X,17,FALSE),0) -> 1 | K9: =IFERROR(VLOOKUP($C9,'World Cup Players'!B:X,18,FALSE),0) -> 0 | L9: =IFERROR(VLOOKUP($C9,'World Cup GK'!B:AE,16,FALSE),0) -> 0 | M9: =IFERROR(VLOOKUP($C9,'World Cup GK'!B:AE,19,FALSE),0) -> 0 | N9: =IFERROR(VLOOKUP($C9,'World Cup GK'!B:AE,14,FALSE),0) -> 0 | O9: =IFERROR(VLOOKUP($C9,'World Cup GK'!B:AE,11,FALSE),0) -> 0 | P9: =SUM((F9*0.0083)+G9+H9+I9+L9+M9+(N9*0.2))-((J9*0.25)+(K9*0.5))-(O9*0.25) -> 5.6839 | S9: Bonnie Mullrooney | T9: =RANK(X9,$X$5:$X$45) -> 34 | U9: Bonnie Mullrooney | V9: =VLOOKUP(U9,$B$4:$P$1245,15,FALSE) -> 171.036 | W9: =0.000000001+W8 -> 1.4e-08 | X9: =V9+W9 -> 171.036 | AB9: 5 | AC9: =VLOOKUP(AB9,$T$5:$V$45,2,FALSE) -> Louise Pickles | AD9: =VLOOKUP(AB9,$T$5:$V$45,3,FALSE) -> 207.184
C10: Mikel Oyarzabal | D10: =IFERROR(VLOOKUP($C10,'World Cup Players'!B:X,3,FALSE),0) -> es Spain | F10: =IFERROR(VLOOKUP($C10,'World Cup Players'!B:X,9,FALSE),0) -> 540 | G10: =IFERROR(VLOOKUP($C10,'World Cup Players'!B:X,11,FALSE),0) -> 5 | H10: =IFERROR(VLOOKUP($C10,'World Cup Players'!B:X,12,FALSE),0) -> 1 | I10: =IFERROR(VLOOKUP($C10,'GAME WINNING GOALS'!A:B,2,FALSE),0) -> 2 | J10: =IFERROR(VLOOKUP($C10,'World Cup Players'!B:X,17,FALSE),0) -> 0 | K10: =IFERROR(VLOOKUP($C10,'World Cup Players'!B:X,18,FALSE),0) -> 0 | L10: =IFERROR(VLOOKUP($C10,'World Cup GK'!B:AE,16,FALSE),0) -> 0 | M10: =IFERROR(VLOOKUP($C10,'World Cup GK'!B:AE,19,FALSE),0) -> 0 | N10: =IFERROR(VLOOKUP($C10,'World Cup GK'!B:AE,14,FALSE),0) -> 0 | O10: =IFERROR(VLOOKUP($C10,'World Cup GK'!B:AE,11,FALSE),0) -> 0 | P10: =SUM((F10*0.0083)+G10+H10+I10+L10+M10+(N10*0.2))-((J10*0.25)+(K10*0.5))-(O10*0.25) -> 12.482 | S10: Michael Formusa | T10: =RANK(X10,$X$5:$X$45) -> 33 | U10: Michael Formusa | V10: =VLOOKUP(U10,$B$4:$P$1245,15,FALSE) -> 171.2772 | W10: =0.000000001+W9 -> 1.5e-08 | X10: =V10+W10 -> 171.2772 | AB10: 6 | AC10: =VLOOKUP(AB10,$T$5:$V$45,2,FALSE) -> Julian Brown | AD10: =VLOOKUP(AB10,$T$5:$V$45,3,FALSE) -> 204.4935
C11: Ismael Saibari | D11: =IFERROR(VLOOKUP($C11,'World Cup Players'!B:X,3,FALSE),0) -> ma Morocco | F11: =IFERROR(VLOOKUP($C11,'World Cup Players'!B:X,9,FALSE),0) -> 381 | G11: =IFERROR(VLOOKUP($C11,'World Cup Players'!B:X,11,FALSE),0) -> 3 | H11: =IFERROR(VLOOKUP($C11,'World Cup Players'!B:X,12,FALSE),0) -> 0 | I11: =IFERROR(VLOOKUP($C11,'GAME WINNING GOALS'!A:B,2,FALSE),0) -> 1 | J11: =IFERROR(VLOOKUP($C11,'World Cup Players'!B:X,17,FALSE),0) -> 0 | K11: =IFERROR(VLOOKUP($C11,'World Cup Players'!B:X,18,FALSE),0) -> 0 | L11: =IFERROR(VLOOKUP($C11,'World Cup GK'!B:AE,16,FALSE),0) -> 0 | M11: =IFERROR(VLOOKUP($C11,'World Cup GK'!B:AE,19,FALSE),0) -> 0 | N11: =IFERROR(VLOOKUP($C11,'World Cup GK'!B:AE,14,FALSE),0) -> 0 | O11: =IFERROR(VLOOKUP($C11,'World Cup GK'!B:AE,11,FALSE),0) -> 0 | P11: =SUM((F11*0.0083)+G11+H11+I11+L11+M11+(N11*0.2))-((J11*0.25)+(K11*0.5))-(O11*0.25) -> 7.1623 | S11: Elyse Lalonde | T11: =RANK(X11,$X$5:$X$45) -> 22 | U11: Elyse Lalonde | V11: =VLOOKUP(U11,$B$4:$P$1245,15,FALSE) -> 184.6213 | W11: =0.000000001+W10 -> 1.6e-08 | X11: =V11+W11 -> 184.6213 | AB11: 7 | AC11: =VLOOKUP(AB11,$T$5:$V$45,2,FALSE) -> Nathan Kessous | AD11: =VLOOKUP(AB11,$T$5:$V$45,3,FALSE) -> 202.827
C12: Bruno Fernandes | D12: =IFERROR(VLOOKUP($C12,'World Cup Players'!B:X,3,FALSE),0) -> pt Portugal | F12: =IFERROR(VLOOKUP($C12,'World Cup Players'!B:X,9,FALSE),0) -> 422 | G12: =IFERROR(VLOOKUP($C12,'World Cup Players'!B:X,11,FALSE),0) -> 0 | H12: =IFERROR(VLOOKUP($C12,'World Cup Players'!B:X,12,FALSE),0) -> 1 | I12: =IFERROR(VLOOKUP($C12,'GAME WINNING GOALS'!A:B,2,FALSE),0) -> 0 | J12: =IFERROR(VLOOKUP($C12,'World Cup Players'!B:X,17,FALSE),0) -> 0 | K12: =IFERROR(VLOOKUP($C12,'World Cup Players'!B:X,18,FALSE),0) -> 0 | L12: =IFERROR(VLOOKUP($C12,'World Cup GK'!B:AE,16,FALSE),0) -> 0 | M12: =IFERROR(VLOOKUP($C12,'World Cup GK'!B:AE,19,FALSE),0) -> 0 | N12: =IFERROR(VLOOKUP($C12,'World Cup GK'!B:AE,14,FALSE),0) -> 0 | O12: =IFERROR(VLOOKUP($C12,'World Cup GK'!B:AE,11,FALSE),0) -> 0 | P12: =SUM((F12*0.0083)+G12+H12+I12+L12+M12+(N12*0.2))-((J12*0.25)+(K12*0.5))-(O12*0.25) -> 4.5026 | S12: Suraj Sukumar | T12: =RANK(X12,$X$5:$X$45) -> 9 | U12: Suraj Sukumar | V12: =VLOOKUP(U12,$B$4:$P$1245,15,FALSE) -> 201.7257 | W12: =0.000000001+W11 -> 1.7e-08 | X12: =V12+W12 -> 201.7257 | AB12: 8 | AC12: =VLOOKUP(AB12,$T$5:$V$45,2,FALSE) -> Victoria Pickles | AD12: =VLOOKUP(AB12,$T$5:$V$45,3,FALSE) -> 202.0984
C13: Leroy Sané | D13: =IFERROR(VLOOKUP($C13,'World Cup Players'!B:X,3,FALSE),0) -> de Germany | F13: =IFERROR(VLOOKUP($C13,'World Cup Players'!B:X,9,FALSE),0) -> 326 | G13: =IFERROR(VLOOKUP($C13,'World Cup Players'!B:X,11,FALSE),0) -> 1 | H13: =IFERROR(VLOOKUP($C13,'World Cup Players'!B:X,12,FALSE),0) -> 0 | I13: =IFERROR(VLOOKUP($C13,'GAME WINNING GOALS'!A:B,2,FALSE),0) -> 0 | J13: =IFERROR(VLOOKUP($C13,'World Cup Players'!B:X,17,FALSE),0) -> 0 | K13: =IFERROR(VLOOKUP($C13,'World Cup Players'!B:X,18,FALSE),0) -> 0 | L13: =IFERROR(VLOOKUP($C13,'World Cup GK'!B:AE,16,FALSE),0) -> 0 | M13: =IFERROR(VLOOKUP($C13,'World Cup GK'!B:AE,19,FALSE),0) -> 0 | N13: =IFERROR(VLOOKUP($C13,'World Cup GK'!B:AE,14,FALSE),0) -> 0 | O13: =IFERROR(VLOOKUP($C13,'World Cup GK'!B:AE,11,FALSE),0) -> 0 | P13: =SUM((F13*0.0083)+G13+H13+I13+L13+M13+(N13*0.2))-((J13*0.25)+(K13*0.5))-(O13*0.25) -> 3.7058 | S13: Bob Reynolds | T13: =RANK(X13,$X$5:$X$45) -> 1 | U13: Bob Reynolds | V13: =VLOOKUP(U13,$B$4:$P$1245,15,FALSE) -> 214.2248 | W13: =0.000000001+W12 -> 1.8e-08 | X13: =V13+W13 -> 214.2248 | AB13: 9 | AC13: =VLOOKUP(AB13,$T$5:$V$45,2,FALSE) -> Suraj Sukumar | AD13: =VLOOKUP(AB13,$T$5:$V$45,3,FALSE) -> 201.7257
C14: Arda Güler | D14: =IFERROR(VLOOKUP($C14,'World Cup Players'!B:X,3,FALSE),0) -> tr Türkiye | F14: =IFERROR(VLOOKUP($C14,'World Cup Players'!B:X,9,FALSE),0) -> 270 | G14: =IFERROR(VLOOKUP($C14,'World Cup Players'!B:X,11,FALSE),0) -> 1 | H14: =IFERROR(VLOOKUP($C14,'World Cup Players'!B:X,12,FALSE),0) -> 0 | I14: =IFERROR(VLOOKUP($C14,'GAME WINNING GOALS'!A:B,2,FALSE),0) -> 0 | J14: =IFERROR(VLOOKUP($C14,'World Cup Players'!B:X,17,FALSE),0) -> 0 | K14: =IFERROR(VLOOKUP($C14,'World Cup Players'!B:X,18,FALSE),0) -> 0 | L14: =IFERROR(VLOOKUP($C14,'World Cup GK'!B:AE,16,FALSE),0) -> 0 | M14: =IFERROR(VLOOKUP($C14,'World Cup GK'!B:AE,19,FALSE),0) -> 0 | N14: =IFERROR(VLOOKUP($C14,'World Cup GK'!B:AE,14,FALSE),0) -> 0 | O14: =IFERROR(VLOOKUP($C14,'World Cup GK'!B:AE,11,FALSE),0) -> 0 | P14: =SUM((F14*0.0083)+G14+H14+I14+L14+M14+(N14*0.2))-((J14*0.25)+(K14*0.5))-(O14*0.25) -> 3.241 | S14: Mark Mullrooney | T14: =RANK(X14,$X$5:$X$45) -> 24 | U14: Mark Mullrooney | V14: =VLOOKUP(U14,$B$4:$P$1245,15,FALSE) -> 181.7636 | W14: =0.000000001+W13 -> 1.9e-08 | X14: =V14+W14 -> 181.7636 | AB14: 10 | AC14: =VLOOKUP(AB14,$T$5:$V$45,2,FALSE) -> John Mullrooney | AD14: =VLOOKUP(AB14,$T$5:$V$45,3,FALSE) -> 199.5535
C15: Jude Bellingham | D15: =IFERROR(VLOOKUP($C15,'World Cup Players'!B:X,3,FALSE),0) -> eng England | F15: =IFERROR(VLOOKUP($C15,'World Cup Players'!B:X,9,FALSE),0) -> 602 | G15: =IFERROR(VLOOKUP($C15,'World Cup Players'!B:X,11,FALSE),0) -> 6 | H15: =IFERROR(VLOOKUP($C15,'World Cup Players'!B:X,12,FALSE),0) -> 1 | I15: =IFERROR(VLOOKUP($C15,'GAME WINNING GOALS'!A:B,2,FALSE),0) -> 3 | J15: =IFERROR(VLOOKUP($C15,'World Cup Players'!B:X,17,FALSE),0) -> 1 | K15: =IFERROR(VLOOKUP($C15,'World Cup Players'!B:X,18,FALSE),0) -> 0 | L15: =IFERROR(VLOOKUP($C15,'World Cup GK'!B:AE,16,FALSE),0) -> 0 | M15: =IFERROR(VLOOKUP($C15,'World Cup GK'!B:AE,19,FALSE),0) -> 0 | N15: =IFERROR(VLOOKUP($C15,'World Cup GK'!B:AE,14,FALSE),0) -> 0 | O15: =IFERROR(VLOOKUP($C15,'World Cup GK'!B:AE,11,FALSE),0) -> 0 | P15: =SUM((F15*0.0083)+G15+H15+I15+L15+M15+(N15*0.2))-((J15*0.25)+(K15*0.5))-(O15*0.25) -> 14.7466 | S15: Paddy McConvey | T15: =RANK(X15,$X$5:$X$45) -> 27 | U15: Paddy McConvey | V15: =VLOOKUP(U15,$B$4:$P$1245,15,FALSE) -> 178.3718 | W15: =0.000000001+W14 -> 2e-08 | X15: =V15+W15 -> 178.3718 | AB15: 11 | AC15: =VLOOKUP(AB15,$T$5:$V$45,2,FALSE) -> Kathleen Mullrooney | AD15: =VLOOKUP(AB15,$T$5:$V$45,3,FALSE) -> 196.2355
C16: Michael Olise | D16: =IFERROR(VLOOKUP($C16,'World Cup Players'!B:X,3,FALSE),0) -> fr France | F16: =IFERROR(VLOOKUP($C16,'World Cup Players'!B:X,9,FALSE),0) -> 556 | G16: =IFERROR(VLOOKUP($C16,'World Cup Players'!B:X,11,FALSE),0) -> 0 | H16: =IFERROR(VLOOKUP($C16,'World Cup Players'!B:X,12,FALSE),0) -> 5 | I16: =IFERROR(VLOOKUP($C16,'GAME WINNING GOALS'!A:B,2,FALSE),0) -> 0 | J16: =IFERROR(VLOOKUP($C16,'World Cup Players'!B:X,17,FALSE),0) -> 1 | K16: =IFERROR(VLOOKUP($C16,'World Cup Players'!B:X,18,FALSE),0) -> 0 | L16: =IFERROR(VLOOKUP($C16,'World Cup GK'!B:AE,16,FALSE),0) -> 0 | M16: =IFERROR(VLOOKUP($C16,'World Cup GK'!B:AE,19,FALSE),0) -> 0 | N16: =IFERROR(VLOOKUP($C16,'World Cup GK'!B:AE,14,FALSE),0) -> 0 | O16: =IFERROR(VLOOKUP($C16,'World Cup GK'!B:AE,11,FALSE),0) -> 0 | P16: =SUM((F16*0.0083)+G16+H16+I16+L16+M16+(N16*0.2))-((J16*0.25)+(K16*0.5))-(O16*0.25) -> 9.3648 | S16: Vishen Maharaj | T16: =RANK(X16,$X$5:$X$45) -> 14 | U16: Vishen Maharaj | V16: =VLOOKUP(U16,$B$4:$P$1245,15,FALSE) -> 194.6317 | W16: =0.000000001+W15 -> 2.1e-08 | X16: =V16+W16 -> 194.6317 | AB16: 12 | AC16: =VLOOKUP(AB16,$T$5:$V$45,2,FALSE) -> Kim Gauthier | AD16: =VLOOKUP(AB16,$T$5:$V$45,3,FALSE) -> 195.3765
C17: Nico Williams | D17: =IFERROR(VLOOKUP($C17,'World Cup Players'!B:X,3,FALSE),0) -> es Spain | F17: =IFERROR(VLOOKUP($C17,'World Cup Players'!B:X,9,FALSE),0) -> 67 | G17: =IFERROR(VLOOKUP($C17,'World Cup Players'!B:X,11,FALSE),0) -> 0 | H17: =IFERROR(VLOOKUP($C17,'World Cup Players'!B:X,12,FALSE),0) -> 0 | I17: =IFERROR(VLOOKUP($C17,'GAME WINNING GOALS'!A:B,2,FALSE),0) -> 0 | J17: =IFERROR(VLOOKUP($C17,'World Cup Players'!B:X,17,FALSE),0) -> 0 | K17: =IFERROR(VLOOKUP($C17,'World Cup Players'!B:X,18,FALSE),0) -> 0 | L17: =IFERROR(VLOOKUP($C17,'World Cup GK'!B:AE,16,FALSE),0) -> 0 | M17: =IFERROR(VLOOKUP($C17,'World Cup GK'!B:AE,19,FALSE),0) -> 0 | N17: =IFERROR(VLOOKUP($C17,'World Cup GK'!B:AE,14,FALSE),0) -> 0 | O17: =IFERROR(VLOOKUP($C17,'World Cup GK'!B:AE,11,FALSE),0) -> 0 | P17: =SUM((F17*0.0083)+G17+H17+I17+L17+M17+(N17*0.2))-((J17*0.25)+(K17*0.5))-(O17*0.25) -> 0.5561 | S17: Naveen Maharaj | T17: =RANK(X17,$X$5:$X$45) -> 25 | U17: Naveen Maharaj | V17: =VLOOKUP(U17,$B$4:$P$1245,15,FALSE) -> 178.7064 | W17: =0.000000001+W16 -> 2.2e-08 | X17: =V17+W17 -> 178.7064 | AB17: 13 | AC17: =VLOOKUP(AB17,$T$5:$V$45,2,FALSE) -> Jacob Posen | AD17: =VLOOKUP(AB17,$T$5:$V$45,3,FALSE) -> 195.016
... C28: Unai Simón | D28: =IFERROR(VLOOKUP($C28,'World Cup Players'!B:X,3,FALSE),0) -> es Spain | F28: =IFERROR(VLOOKUP($C28,'World Cup Players'!B:X,9,FALSE),0) -> 630 | G28: =IFERROR(VLOOKUP($C28,'World Cup Players'!B:X,11,FALSE),0) -> 0 | H28: =IFERROR(VLOOKUP($C28,'World Cup Players'!B:X,12,FALSE),0) -> 0 | I28: =IFERROR(VLOOKUP($C28,'GAME WINNING GOALS'!A:B,2,FALSE),0) -> 0 | J28: =IFERROR(VLOOKUP($C28,'World Cup Players'!B:X,17,FALSE),0) -> 0 | K28: =IFERROR(VLOOKUP($C28,'World Cup Players'!B:X,18,FALSE),0) -> 0 | L28: =IFERROR(VLOOKUP($C28,'World Cup GK'!B:AE,16,FALSE),0) -> 6 | M28: =IFERROR(VLOOKUP($C28,'World Cup GK'!B:AE,19,FALSE),0) -> 6 | N28: =IFERROR(VLOOKUP($C28,'World Cup GK'!B:AE,14,FALSE),0) -> 9 | O28: =IFERROR(VLOOKUP($C28,'World Cup GK'!B:AE,11,FALSE),0) -> 1 | P28: =SUM((F28*0.0083)+G28+H28+I28+L28+M28+(N28*0.2))-((J28*0.25)+(K28*0.5))-(O28*0.25) -> 18.779 | S28: Brian Ihnacak | T28: =RANK(X28,$X$5:$X$45) -> 4 | U28: Brian Ihnacak | V28: =VLOOKUP(U28,$B$4:$P$1245,15,FALSE) -> 208.8653 | W28: =0.000000001+W27 -> 3.3e-08 | X28: =V28+W28 -> 208.8653 | AB28: 24 | AC28: =VLOOKUP(AB28,$T$5:$V$45,2,FALSE) -> Mark Mullrooney | AD28: =VLOOKUP(AB28,$T$5:$V$45,3,FALSE) -> 181.7636
C29: Jordan Pickford | D29: =IFERROR(VLOOKUP($C29,'World Cup Players'!B:X,3,FALSE),0) -> eng England | F29: =IFERROR(VLOOKUP($C29,'World Cup Players'!B:X,9,FALSE),0) -> 660 | G29: =IFERROR(VLOOKUP($C29,'World Cup Players'!B:X,11,FALSE),0) -> 0 | H29: =IFERROR(VLOOKUP($C29,'World Cup Players'!B:X,12,FALSE),0) -> 0 | I29: =IFERROR(VLOOKUP($C29,'GAME WINNING GOALS'!A:B,2,FALSE),0) -> 0 | J29: =IFERROR(VLOOKUP($C29,'World Cup Players'!B:X,17,FALSE),0) -> 0 | K29: =IFERROR(VLOOKUP($C29,'World Cup Players'!B:X,18,FALSE),0) -> 0 | L29: =IFERROR(VLOOKUP($C29,'World Cup GK'!B:AE,16,FALSE),0) -> 5 | M29: =IFERROR(VLOOKUP($C29,'World Cup GK'!B:AE,19,FALSE),0) -> 2 | N29: =IFERROR(VLOOKUP($C29,'World Cup GK'!B:AE,14,FALSE),0) -> 15 | O29: =IFERROR(VLOOKUP($C29,'World Cup GK'!B:AE,11,FALSE),0) -> 8 | P29: =SUM((F29*0.0083)+G29+H29+I29+L29+M29+(N29*0.2))-((J29*0.25)+(K29*0.5)+(O29*0.25)) -> 13.478 | S29: Jeff Bigelow | T29: =RANK(X29,$X$5:$X$45) -> 40 | U29: Jeff Bigelow | V29: =VLOOKUP(U29,$B$4:$P$1245,15,FALSE) -> 160.9949 | W29: =0.000000001+W28 -> 3.4e-08 | X29: =V29+W29 -> 160.9949 | AB29: 25 | AC29: =VLOOKUP(AB29,$T$5:$V$45,2,FALSE) -> Naveen Maharaj | AD29: =VLOOKUP(AB29,$T$5:$V$45,3,FALSE) -> 178.7064
C30: Yassine Bounou | D30: =IFERROR(VLOOKUP($C30,'World Cup Players'!B:X,3,FALSE),0) -> ma Morocco | F30: =IFERROR(VLOOKUP($C30,'World Cup Players'!B:X,9,FALSE),0) -> 570 | G30: =IFERROR(VLOOKUP($C30,'World Cup Players'!B:X,11,FALSE),0) -> 0 | H30: =IFERROR(VLOOKUP($C30,'World Cup Players'!B:X,12,FALSE),0) -> 0 | I30: =IFERROR(VLOOKUP($C30,'GAME WINNING GOALS'!A:B,2,FALSE),0) -> 0 | J30: =IFERROR(VLOOKUP($C30,'World Cup Players'!B:X,17,FALSE),0) -> 0 | K30: =IFERROR(VLOOKUP($C30,'World Cup Players'!B:X,18,FALSE),0) -> 0 | L30: =IFERROR(VLOOKUP($C30,'World Cup GK'!B:AE,16,FALSE),0) -> 3 | M30: =IFERROR(VLOOKUP($C30,'World Cup GK'!B:AE,19,FALSE),0) -> 2 | N30: =IFERROR(VLOOKUP($C30,'World Cup GK'!B:AE,14,FALSE),0) -> 14 | O30: =IFERROR(VLOOKUP($C30,'World Cup GK'!B:AE,11,FALSE),0) -> 6 | P30: =SUM((F30*0.0083)+G30+H30+I30+L30+M30+(N30*0.2))-((J30*0.25)+(K30*0.5))-(O30*0.25) -> 11.031 | S30: Steve Mastoras | T30: =RANK(X30,$X$5:$X$45) -> 26 | U30: Steve Mastoras | V30: =VLOOKUP(U30,$B$4:$P$1245,15,FALSE) -> 178.4533 | W30: =0.000000001+W29 -> 3.5e-08 | X30: =V30+W30 -> 178.4533 | AB30: 26 | AC30: =VLOOKUP(AB30,$T$5:$V$45,2,FALSE) -> Steve Mastoras | AD30: =VLOOKUP(AB30,$T$5:$V$45,3,FALSE) -> 178.4533
C31: Ørjan Nyland | D31: =IFERROR(VLOOKUP($C31,'World Cup Players'!B:X,3,FALSE),0) -> no Norway | F31: =IFERROR(VLOOKUP($C31,'World Cup Players'!B:X,9,FALSE),0) -> 480 | G31: =IFERROR(VLOOKUP($C31,'World Cup Players'!B:X,11,FALSE),0) -> 0 | H31: =IFERROR(VLOOKUP($C31,'World Cup Players'!B:X,12,FALSE),0) -> 0 | I31: =IFERROR(VLOOKUP($C31,'GAME WINNING GOALS'!A:B,2,FALSE),0) -> 0 | J31: =IFERROR(VLOOKUP($C31,'World Cup Players'!B:X,17,FALSE),0) -> 0 | K31: =IFERROR(VLOOKUP($C31,'World Cup Players'!B:X,18,FALSE),0) -> 0 | L31: =IFERROR(VLOOKUP($C31,'World Cup GK'!B:AE,16,FALSE),0) -> 4 | M31: =IFERROR(VLOOKUP($C31,'World Cup GK'!B:AE,19,FALSE),0) -> 0 | N31: =IFERROR(VLOOKUP($C31,'World Cup GK'!B:AE,14,FALSE),0) -> 15 | O31: =IFERROR(VLOOKUP($C31,'World Cup GK'!B:AE,11,FALSE),0) -> 7 | P31: =SUM((F31*0.0083)+G31+H31+I31+L31+M31+(N31*0.2))-((J31*0.25)+(K31*0.5))-(O31*0.25) -> 9.234 | S31: Louise Pickles | T31: =RANK(X31,$X$5:$X$45) -> 5 | U31: Louise Pickles | V31: =VLOOKUP(U31,$B$4:$P$1245,15,FALSE) -> 207.184 | W31: =0.000000001+W30 -> 3.6e-08 | X31: =V31+W31 -> 207.184 | AB31: 27 | AC31: =VLOOKUP(AB31,$T$5:$V$45,2,FALSE) -> Paddy McConvey | AD31: =VLOOKUP(AB31,$T$5:$V$45,3,FALSE) -> 178.3718
C32: Maxime Crépeau | D32: =IFERROR(VLOOKUP($C32,'World Cup Players'!B:X,3,FALSE),0) -> ca Canada | F32: =IFERROR(VLOOKUP($C32,'World Cup Players'!B:X,9,FALSE),0) -> 450 | G32: =IFERROR(VLOOKUP($C32,'World Cup Players'!B:X,11,FALSE),0) -> 0 | H32: =IFERROR(VLOOKUP($C32,'World Cup Players'!B:X,12,FALSE),0) -> 0 | I32: =IFERROR(VLOOKUP($C32,'GAME WINNING GOALS'!A:B,2,FALSE),0) -> 0 | J32: =IFERROR(VLOOKUP($C32,'World Cup Players'!B:X,17,FALSE),0) -> 0 | K32: =IFERROR(VLOOKUP($C32,'World Cup Players'!B:X,18,FALSE),0) -> 0 | L32: =IFERROR(VLOOKUP($C32,'World Cup GK'!B:AE,16,FALSE),0) -> 2 | M32: =IFERROR(VLOOKUP($C32,'World Cup GK'!B:AE,19,FALSE),0) -> 2 | N32: =IFERROR(VLOOKUP($C32,'World Cup GK'!B:AE,14,FALSE),0) -> 6 | O32: =IFERROR(VLOOKUP($C32,'World Cup GK'!B:AE,11,FALSE),0) -> 6 | P32: =SUM((F32*0.0083)+G32+H32+I32+L32+M32+(N32*0.2))-((J32*0.25)+(K32*0.5))-(O32*0.25) -> 7.435 | S32: Rod Akins | T32: =RANK(X32,$X$5:$X$45) -> 30 | U32: Rod Akins | V32: =VLOOKUP(U32,$B$4:$P$1245,15,FALSE) -> 174.0397 | W32: =0.000000001+W31 -> 3.7e-08 | X32: =V32+W32 -> 174.0397 | AB32: 28 | AC32: =VLOOKUP(AB32,$T$5:$V$45,2,FALSE) -> Ivan Cajic | AD32: =VLOOKUP(AB32,$T$5:$V$45,3,FALSE) -> 176.3733
C33: ENGLAND | D33: =IFERROR(VLOOKUP($C33,'World Cup Players'!B:X,3,FALSE),0) -> 0 | F33: =IFERROR(VLOOKUP($C33,'World Cup Players'!B:X,9,FALSE),0) -> 0 | G33: =IFERROR(VLOOKUP($C33,'World Cup Players'!B:X,11,FALSE),0) -> 0 | H33: 0 | I33: =IFERROR(VLOOKUP($C33,'GAME WINNING GOALS'!A:B,2,FALSE),0) -> 1 | J33: =IFERROR(VLOOKUP($C33,'World Cup Players'!B:X,17,FALSE),0) -> 0 | K33: =IFERROR(VLOOKUP($C33,'World Cup Players'!B:X,18,FALSE),0) -> 0 | L33: =IFERROR(VLOOKUP($C33,'World Cup GK'!B:AE,16,FALSE),0) -> 0 | M33: =IFERROR(VLOOKUP($C33,'World Cup GK'!B:AE,19,FALSE),0) -> 0 | N33: =IFERROR(VLOOKUP($C33,'World Cup GK'!B:AE,14,FALSE),0) -> 0 | O33: =IFERROR(VLOOKUP($C33,'World Cup GK'!B:AE,11,FALSE),0) -> 0 | P33: =SUM((F33*0.0083)+G33+H33+I33+L33+M33+(N33*0.2))-((J33*0.25)+(K33*0.5))-(O33*0.25) -> 1 | S33: Andy MacDonald | T33: =RANK(X33,$X$5:$X$45) -> 21 | U33: Andy MacDonald | V33: =VLOOKUP(U33,$B$4:$P$1245,15,FALSE) -> 186.7096 | W33: =0.000000001+W32 -> 3.8e-08 | X33: =V33+W33 -> 186.7096 | AB33: 29 | AC33: =VLOOKUP(AB33,$T$5:$V$45,2,FALSE) -> Kevin Kernohan | AD33: =VLOOKUP(AB33,$T$5:$V$45,3,FALSE) -> 175.7492
C34: SPAIN | D34: =IFERROR(VLOOKUP($C34,'World Cup Players'!B:X,3,FALSE),0) -> 0 | F34: =IFERROR(VLOOKUP($C34,'World Cup Players'!B:X,9,FALSE),0) -> 0 | G34: =IFERROR(VLOOKUP($C34,'World Cup Players'!B:X,11,FALSE),0) -> 0 | H34: 2 | I34: =IFERROR(VLOOKUP($C34,'GAME WINNING GOALS'!A:B,2,FALSE),0) -> 1 | J34: =IFERROR(VLOOKUP($C34,'World Cup Players'!B:X,17,FALSE),0) -> 0 | K34: =IFERROR(VLOOKUP($C34,'World Cup Players'!B:X,18,FALSE),0) -> 0 | L34: =IFERROR(VLOOKUP($C34,'World Cup GK'!B:AE,16,FALSE),0) -> 0 | M34: =IFERROR(VLOOKUP($C34,'World Cup GK'!B:AE,19,FALSE),0) -> 0 | N34: =IFERROR(VLOOKUP($C34,'World Cup GK'!B:AE,14,FALSE),0) -> 0 | O34: =IFERROR(VLOOKUP($C34,'World Cup GK'!B:AE,11,FALSE),0) -> 0 | P34: =SUM((F34*0.0083)+G34+H34+I34+L34+M34+(N34*0.2))-((J34*0.25)+(K34*0.5))-(O34*0.25) -> 3 | S34: John Mullrooney | T34: =RANK(X34,$X$5:$X$45) -> 10 | U34: John Mullrooney | V34: =VLOOKUP(U34,$B$4:$P$1245,15,FALSE) -> 199.5535 | W34: =0.000000001+W33 -> 3.9e-08 | X34: =V34+W34 -> 199.5535 | AB34: 30 | AC34: =VLOOKUP(AB34,$T$5:$V$45,2,FALSE) -> Rod Akins | AD34: =VLOOKUP(AB34,$T$5:$V$45,3,FALSE) -> 174.0397
C35: BRAZIL | D35: =IFERROR(VLOOKUP($C35,'World Cup Players'!B:X,3,FALSE),0) -> 0 | F35: =IFERROR(VLOOKUP($C35,'World Cup Players'!B:X,9,FALSE),0) -> 0 | G35: =IFERROR(VLOOKUP($C35,'World Cup Players'!B:X,11,FALSE),0) -> 0 | H35: =IFERROR(VLOOKUP($C35,'World Cup Players'!B:X,12,FALSE),0) -> 0 | I35: =IFERROR(VLOOKUP($C35,'GAME WINNING GOALS'!A:B,2,FALSE),0) -> 0 | J35: =IFERROR(VLOOKUP($C35,'World Cup Players'!B:X,17,FALSE),0) -> 0 | K35: =IFERROR(VLOOKUP($C35,'World Cup Players'!B:X,18,FALSE),0) -> 0 | L35: =IFERROR(VLOOKUP($C35,'World Cup GK'!B:AE,16,FALSE),0) -> 0 | M35: =IFERROR(VLOOKUP($C35,'World Cup GK'!B:AE,19,FALSE),0) -> 0 | N35: =IFERROR(VLOOKUP($C35,'World Cup GK'!B:AE,14,FALSE),0) -> 0 | O35: =IFERROR(VLOOKUP($C35,'World Cup GK'!B:AE,11,FALSE),0) -> 0 | P35: =SUM((F35*0.0083)+G35+H35+I35+L35+M35+(N35*0.2))-((J35*0.25)+(K35*0.5))-(O35*0.25) -> 0 | S35: Patrick Mullrooney | T35: =RANK(X35,$X$5:$X$45) -> 19 | U35: Patrick Mullrooney | V35: =VLOOKUP(U35,$B$4:$P$1245,15,FALSE) -> 188.5115 | W35: =0.000000001+W34 -> 4e-08 | X35: =V35+W35 -> 188.5115 | AB35: 31 | AC35: =VLOOKUP(AB35,$T$5:$V$45,2,FALSE) -> Tom Mullrooney | AD35: =VLOOKUP(AB35,$T$5:$V$45,3,FALSE) -> 173.0693
B36: Eleni Mastoras | D36: =SUM(D37:D61) -> 0 | E36: =SUM(E37:E61) -> 0 | F36: =SUM(F37:F66) -> 11165 | G36: =SUM(G37:G66) -> 26 | H36: =SUM(H37:H66) -> 21 | I36: =SUM(I37:I66) -> 11 | J36: =SUM(J37:J66) -> 10 | K36: =SUM(K37:K66) -> 1 | L36: =SUM(L37:L66) -> 13 | M36: =SUM(M37:M66) -> 6 | ... O36: =SUM(O37:O66) -> 27 | P36: =SUM((F36*0.0083)+G36+H36+I36+L36+M36+(N36*0.2))-((J36*0.25)+(K36*0.5))-(O36*0.25) -> 168.7195 | S36: Kim Gauthier | T36: =RANK(X36,$X$5:$X$45) -> 12 | U36: Kim Gauthier | V36: =VLOOKUP(U36,$B$4:$P$1245,15,FALSE) -> 195.3765 | W36: =0.000000001+W35 -> 4.1e-08 | X36: =V36+W36 -> 195.3765 | AB36: 32 | AC36: =VLOOKUP(AB36,$T$5:$V$45,2,FALSE) -> Hudson Algor | AD36: =VLOOKUP(AB36,$T$5:$V$45,3,FALSE) -> 172.8513
C37: Kylian Mbappé | D37: =IFERROR(VLOOKUP($C37,'World Cup Players'!B:X,3,FALSE),0) -> fr France | F37: =IFERROR(VLOOKUP($C37,'World Cup Players'!B:X,9,FALSE),0) -> 605 | G37: =IFERROR(VLOOKUP($C37,'World Cup Players'!B:X,11,FALSE),0) -> 8 | H37: =IFERROR(VLOOKUP($C37,'World Cup Players'!B:X,12,FALSE),0) -> 3 | I37: =IFERROR(VLOOKUP($C37,'GAME WINNING GOALS'!A:B,2,FALSE),0) -> 4 | J37: =IFERROR(VLOOKUP($C37,'World Cup Players'!B:X,17,FALSE),0) -> 1 | K37: =IFERROR(VLOOKUP($C37,'World Cup Players'!B:X,18,FALSE),0) -> 0 | L37: =IFERROR(VLOOKUP($C37,'World Cup GK'!B:AE,16,FALSE),0) -> 0 | M37: =IFERROR(VLOOKUP($C37,'World Cup GK'!B:AE,19,FALSE),0) -> 0 | N37: =IFERROR(VLOOKUP($C37,'World Cup GK'!B:AE,14,FALSE),0) -> 0 | O37: =IFERROR(VLOOKUP($C37,'World Cup GK'!B:AE,11,FALSE),0) -> 0 | P37: =SUM((F37*0.0083)+G37+H37+I37+L37+M37+(N37*0.2))-((J37*0.25)+(K37*0.5))-(O37*0.25) -> 19.7715 | S37: Maureen Mullrooney | T37: =RANK(X37,$X$5:$X$45) -> 39 | U37: Maureen Mullrooney | V37: =VLOOKUP(U37,$B$4:$P$1245,15,FALSE) -> 161.2094 | W37: =0.000000001+W36 -> 4.2e-08 | X37: =V37+W37 -> 161.2094 | AB37: 33 | AC37: =VLOOKUP(AB37,$T$5:$V$45,2,FALSE) -> Michael Formusa | AD37: =VLOOKUP(AB37,$T$5:$V$45,3,FALSE) -> 171.2772
C38: Marcus Thuram | D38: =IFERROR(VLOOKUP($C38,'World Cup Players'!B:X,3,FALSE),0) -> fr France | F38: =IFERROR(VLOOKUP($C38,'World Cup Players'!B:X,9,FALSE),0) -> 1 | G38: =IFERROR(VLOOKUP($C38,'World Cup Players'!B:X,11,FALSE),0) -> 0 | H38: =IFERROR(VLOOKUP($C38,'World Cup Players'!B:X,12,FALSE),0) -> 0 | I38: =IFERROR(VLOOKUP($C38,'GAME WINNING GOALS'!A:B,2,FALSE),0) -> 0 | J38: =IFERROR(VLOOKUP($C38,'World Cup Players'!B:X,17,FALSE),0) -> 0 | K38: =IFERROR(VLOOKUP($C38,'World Cup Players'!B:X,18,FALSE),0) -> 0 | L38: =IFERROR(VLOOKUP($C38,'World Cup GK'!B:AE,16,FALSE),0) -> 0 | M38: =IFERROR(VLOOKUP($C38,'World Cup GK'!B:AE,19,FALSE),0) -> 0 | N38: =IFERROR(VLOOKUP($C38,'World Cup GK'!B:AE,14,FALSE),0) -> 0 | O38: =IFERROR(VLOOKUP($C38,'World Cup GK'!B:AE,11,FALSE),0) -> 0 | P38: =SUM((F38*0.0083)+G38+H38+I38+L38+M38+(N38*0.2))-((J38*0.25)+(K38*0.5))-(O38*0.25) -> 0.0083 | S38: Brian Jefferson | T38: =RANK(X38,$X$5:$X$45) -> 37 | U38: Brian Jefferson | V38: =VLOOKUP(U38,$B$4:$P$1245,15,FALSE) -> 165.0522 | W38: =0.000000001+W37 -> 4.3e-08 | X38: =V38+W38 -> 165.0522 | AB38: 34 | AC38: =VLOOKUP(AB38,$T$5:$V$45,2,FALSE) -> Bonnie Mullrooney | AD38: =VLOOKUP(AB38,$T$5:$V$45,3,FALSE) -> 171.036
C39: Breel Embolo | D39: =IFERROR(VLOOKUP($C39,'World Cup Players'!B:X,3,FALSE),0) -> ch Switzerland | F39: =IFERROR(VLOOKUP($C39,'World Cup Players'!B:X,9,FALSE),0) -> 501 | G39: =IFERROR(VLOOKUP($C39,'World Cup Players'!B:X,11,FALSE),0) -> 2 | H39: =IFERROR(VLOOKUP($C39,'World Cup Players'!B:X,12,FALSE),0) -> 2 | I39: =IFERROR(VLOOKUP($C39,'GAME WINNING GOALS'!A:B,2,FALSE),0) -> 1 | J39: =IFERROR(VLOOKUP($C39,'World Cup Players'!B:X,17,FALSE),0) -> 2 | K39: =IFERROR(VLOOKUP($C39,'World Cup Players'!B:X,18,FALSE),0) -> 1 | L39: =IFERROR(VLOOKUP($C39,'World Cup GK'!B:AE,16,FALSE),0) -> 0 | M39: =IFERROR(VLOOKUP($C39,'World Cup GK'!B:AE,19,FALSE),0) -> 0 | N39: =IFERROR(VLOOKUP($C39,'World Cup GK'!B:AE,14,FALSE),0) -> 0 | O39: =IFERROR(VLOOKUP($C39,'World Cup GK'!B:AE,11,FALSE),0) -> 0 | P39: =SUM((F39*0.0083)+G39+H39+I39+L39+M39+(N39*0.2))-((J39*0.25)+(K39*0.5))-(O39*0.25) -> 8.1583 | S39: Jacob Posen | T39: =RANK(X39,$X$5:$X$45) -> 13 | U39: Jacob Posen | V39: =VLOOKUP(U39,$B$4:$P$1245,15,FALSE) -> 195.016 | W39: =0.000000001+W38 -> 4.4e-08 | X39: =V39+W39 -> 195.016 | AB39: 35 | AC39: =VLOOKUP(AB39,$T$5:$V$45,2,FALSE) -> Eleni Mastoras | AD39: =VLOOKUP(AB39,$T$5:$V$45,3,FALSE) -> 168.7195
C40: Ousmane Dembélé | D40: =IFERROR(VLOOKUP($C40,'World Cup Players'!B:X,3,FALSE),0) -> fr France | F40: =IFERROR(VLOOKUP($C40,'World Cup Players'!B:X,9,FALSE),0) -> 547 | G40: =IFERROR(VLOOKUP($C40,'World Cup Players'!B:X,11,FALSE),0) -> 5 | H40: =IFERROR(VLOOKUP($C40,'World Cup Players'!B:X,12,FALSE),0) -> 2 | I40: =IFERROR(VLOOKUP($C40,'GAME WINNING GOALS'!A:B,2,FALSE),0) -> 1 | J40: =IFERROR(VLOOKUP($C40,'World Cup Players'!B:X,17,FALSE),0) -> 0 | K40: =IFERROR(VLOOKUP($C40,'World Cup Players'!B:X,18,FALSE),0) -> 0 | L40: =IFERROR(VLOOKUP($C40,'World Cup GK'!B:AE,16,FALSE),0) -> 0 | M40: =IFERROR(VLOOKUP($C40,'World Cup GK'!B:AE,19,FALSE),0) -> 0 | N40: =IFERROR(VLOOKUP($C40,'World Cup GK'!B:AE,14,FALSE),0) -> 0 | O40: =IFERROR(VLOOKUP($C40,'World Cup GK'!B:AE,11,FALSE),0) -> 0 | P40: =SUM((F40*0.0083)+G40+H40+I40+L40+M40+(N40*0.2))-((J40*0.25)+(K40*0.5))-(O40*0.25) -> 12.5401 | S40: Nathan Kessous | T40: =RANK(X40,$X$5:$X$45) -> 7 | U40: Nathan Kessous | V40: =VLOOKUP(U40,$B$4:$P$1245,15,FALSE) -> 202.827 | W40: =0.000000001+W39 -> 4.5e-08 | X40: =V40+W40 -> 202.827 | AB40: 36 | AC40: =VLOOKUP(AB40,$T$5:$V$45,2,FALSE) -> Kathryn Schierling | AD40: =VLOOKUP(AB40,$T$5:$V$45,3,FALSE) -> 167.2098
C41: Mikel Oyarzabal | D41: =IFERROR(VLOOKUP($C41,'World Cup Players'!B:X,3,FALSE),0) -> es Spain | F41: =IFERROR(VLOOKUP($C41,'World Cup Players'!B:X,9,FALSE),0) -> 540 | G41: =IFERROR(VLOOKUP($C41,'World Cup Players'!B:X,11,FALSE),0) -> 5 | H41: =IFERROR(VLOOKUP($C41,'World Cup Players'!B:X,12,FALSE),0) -> 1 | I41: =IFERROR(VLOOKUP($C41,'GAME WINNING GOALS'!A:B,2,FALSE),0) -> 2 | J41: =IFERROR(VLOOKUP($C41,'World Cup Players'!B:X,17,FALSE),0) -> 0 | K41: =IFERROR(VLOOKUP($C41,'World Cup Players'!B:X,18,FALSE),0) -> 0 | L41: =IFERROR(VLOOKUP($C41,'World Cup GK'!B:AE,16,FALSE),0) -> 0 | M41: =IFERROR(VLOOKUP($C41,'World Cup GK'!B:AE,19,FALSE),0) -> 0 | N41: =IFERROR(VLOOKUP($C41,'World Cup GK'!B:AE,14,FALSE),0) -> 0 | O41: =IFERROR(VLOOKUP($C41,'World Cup GK'!B:AE,11,FALSE),0) -> 0 | P41: =SUM((F41*0.0083)+G41+H41+I41+L41+M41+(N41*0.2))-((J41*0.25)+(K41*0.5))-(O41*0.25) -> 12.482 | S41: Justin Algor | T41: =RANK(X41,$X$5:$X$45) -> 17 | U41: Justin Algor | V41: =VLOOKUP(U41,$B$4:$P$1245,15,FALSE) -> 190.1306 | W41: =0.000000001+W40 -> 4.6e-08 | X41: =V41+W41 -> 190.1306 | AB41: 37 | AC41: =VLOOKUP(AB41,$T$5:$V$45,2,FALSE) -> Brian Jefferson | AD41: =VLOOKUP(AB41,$T$5:$V$45,3,FALSE) -> 165.0522
C42: Rodri | D42: =IFERROR(VLOOKUP($C42,'World Cup Players'!B:X,3,FALSE),0) -> es Spain | F42: =IFERROR(VLOOKUP($C42,'World Cup Players'!B:X,9,FALSE),0) -> 626 | G42: =IFERROR(VLOOKUP($C42,'World Cup Players'!B:X,11,FALSE),0) -> 0 | H42: =IFERROR(VLOOKUP($C42,'World Cup Players'!B:X,12,FALSE),0) -> 0 | I42: =IFERROR(VLOOKUP($C42,'GAME WINNING GOALS'!A:B,2,FALSE),0) -> 0 | J42: =IFERROR(VLOOKUP($C42,'World Cup Players'!B:X,17,FALSE),0) -> 0 | K42: =IFERROR(VLOOKUP($C42,'World Cup Players'!B:X,18,FALSE),0) -> 0 | L42: =IFERROR(VLOOKUP($C42,'World Cup GK'!B:AE,16,FALSE),0) -> 0 | M42: =IFERROR(VLOOKUP($C42,'World Cup GK'!B:AE,19,FALSE),0) -> 0 | N42: =IFERROR(VLOOKUP($C42,'World Cup GK'!B:AE,14,FALSE),0) -> 0 | O42: =IFERROR(VLOOKUP($C42,'World Cup GK'!B:AE,11,FALSE),0) -> 0 | P42: =SUM((F42*0.0083)+G42+H42+I42+L42+M42+(N42*0.2))-((J42*0.25)+(K42*0.5))-(O42*0.25) -> 5.1958 | S42: Hudson Algor | T42: =RANK(X42,$X$5:$X$45) -> 32 | U42: Hudson Algor | V42: =VLOOKUP(U42,$B$4:$P$1245,15,FALSE) -> 172.8513 | W42: =0.000000001+W41 -> 4.7e-08 | X42: =V42+W42 -> 172.8513 | AB42: 38 | AC42: =VLOOKUP(AB42,$T$5:$V$45,2,FALSE) -> Julian Santia | AD42: =VLOOKUP(AB42,$T$5:$V$45,3,FALSE) -> 162.7527
C43: Aurélien Tchouaméni | D43: =IFERROR(VLOOKUP($C43,'World Cup Players'!B:X,3,FALSE),0) -> fr France | F43: =IFERROR(VLOOKUP($C43,'World Cup Players'!B:X,9,FALSE),0) -> 360 | G43: =IFERROR(VLOOKUP($C43,'World Cup Players'!B:X,11,FALSE),0) -> 0 | H43: =IFERROR(VLOOKUP($C43,'World Cup Players'!B:X,12,FALSE),0) -> 1 | I43: =IFERROR(VLOOKUP($C43,'GAME WINNING GOALS'!A:B,2,FALSE),0) -> 0 | J43: =IFERROR(VLOOKUP($C43,'World Cup Players'!B:X,17,FALSE),0) -> 1 | K43: =IFERROR(VLOOKUP($C43,'World Cup Players'!B:X,18,FALSE),0) -> 0 | L43: =IFERROR(VLOOKUP($C43,'World Cup GK'!B:AE,16,FALSE),0) -> 0 | M43: =IFERROR(VLOOKUP($C43,'World Cup GK'!B:AE,19,FALSE),0) -> 0 | N43: =IFERROR(VLOOKUP($C43,'World Cup GK'!B:AE,14,FALSE),0) -> 0 | O43: =IFERROR(VLOOKUP($C43,'World Cup GK'!B:AE,11,FALSE),0) -> 0 | P43: =SUM((F43*0.0083)+G43+H43+I43+L43+M43+(N43*0.2))-((J43*0.25)+(K43*0.5))-(O43*0.25) -> 3.738 | S43: Thayer Algor | T43: =RANK(X43,$X$5:$X$45) -> 2 | U43: Thayer Algor | V43: =VLOOKUP(U43,$B$4:$P$1245,15,FALSE) -> 214.0375 | W43: =0.000000001+W42 -> 4.8e-08 | X43: =V43+W43 -> 214.0375 | AB43: 39 | AC43: =VLOOKUP(AB43,$T$5:$V$45,2,FALSE) -> Maureen Mullrooney | AD43: =VLOOKUP(AB43,$T$5:$V$45,3,FALSE) -> 161.2094
C44: Alexis Mac Allister | D44: =IFERROR(VLOOKUP($C44,'World Cup Players'!B:X,3,FALSE),0) -> ar Argentina | F44: =IFERROR(VLOOKUP($C44,'World Cup Players'!B:X,9,FALSE),0) -> 630 | G44: =IFERROR(VLOOKUP($C44,'World Cup Players'!B:X,11,FALSE),0) -> 1 | H44: =IFERROR(VLOOKUP($C44,'World Cup Players'!B:X,12,FALSE),0) -> 1 | I44: =IFERROR(VLOOKUP($C44,'GAME WINNING GOALS'!A:B,2,FALSE),0) -> 0 | J44: =IFERROR(VLOOKUP($C44,'World Cup Players'!B:X,17,FALSE),0) -> 0 | K44: =IFERROR(VLOOKUP($C44,'World Cup Players'!B:X,18,FALSE),0) -> 0 | L44: =IFERROR(VLOOKUP($C44,'World Cup GK'!B:AE,16,FALSE),0) -> 0 | M44: =IFERROR(VLOOKUP($C44,'World Cup GK'!B:AE,19,FALSE),0) -> 0 | N44: =IFERROR(VLOOKUP($C44,'World Cup GK'!B:AE,14,FALSE),0) -> 0 | O44: =IFERROR(VLOOKUP($C44,'World Cup GK'!B:AE,11,FALSE),0) -> 0 | P44: =SUM((F44*0.0083)+G44+H44+I44+L44+M44+(N44*0.2))-((J44*0.25)+(K44*0.5))-(O44*0.25) -> 7.229 | S44: Julian Brown | T44: =RANK(X44,$X$5:$X$45) -> 6 | U44: Julian Brown | V44: =VLOOKUP(U44,$B$4:$P$1245,15,FALSE) -> 204.4935 | W44: =0.000000001+W43 -> 4.9e-08 | X44: =V44+W44 -> 204.4935 | AB44: 40 | AC44: =VLOOKUP(AB44,$T$5:$V$45,2,FALSE) -> Jeff Bigelow | AD44: =VLOOKUP(AB44,$T$5:$V$45,3,FALSE) -> 160.9949
C45: Ayase Ueda | D45: =IFERROR(VLOOKUP($C45,'World Cup Players'!B:X,3,FALSE),0) -> jp Japan | F45: =IFERROR(VLOOKUP($C45,'World Cup Players'!B:X,9,FALSE),0) -> 321 | G45: =IFERROR(VLOOKUP($C45,'World Cup Players'!B:X,11,FALSE),0) -> 2 | H45: =IFERROR(VLOOKUP($C45,'World Cup Players'!B:X,12,FALSE),0) -> 1 | I45: =IFERROR(VLOOKUP($C45,'GAME WINNING GOALS'!A:B,2,FALSE),0) -> 0 | J45: =IFERROR(VLOOKUP($C45,'World Cup Players'!B:X,17,FALSE),0) -> 0 | K45: =IFERROR(VLOOKUP($C45,'World Cup Players'!B:X,18,FALSE),0) -> 0 | L45: =IFERROR(VLOOKUP($C45,'World Cup GK'!B:AE,16,FALSE),0) -> 0 | M45: =IFERROR(VLOOKUP($C45,'World Cup GK'!B:AE,19,FALSE),0) -> 0 | N45: =IFERROR(VLOOKUP($C45,'World Cup GK'!B:AE,14,FALSE),0) -> 0 | O45: =IFERROR(VLOOKUP($C45,'World Cup GK'!B:AE,11,FALSE),0) -> 0 | P45: =SUM((F45*0.0083)+G45+H45+I45+L45+M45+(N45*0.2))-((J45*0.25)+(K45*0.5))-(O45*0.25) -> 5.6643 | T45: =RANK(X45,$X$5:$X$45) -> 16 | U45: Leo Mastoras | V45: =VLOOKUP(U45,$B$4:$P$1245,15,FALSE) -> 191.5771 | W45: =0.000000001+W44 -> 5e-08 | X45: =V45+W45 -> 191.5771 | AB45: 41 | AC45: =VLOOKUP(AB45,$T$5:$V$45,2,FALSE) -> Louise Kanopoulos | AD45: =VLOOKUP(AB45,$T$5:$V$45,3,FALSE) -> 156.2515 | AI45: Julian Santia | AJ45: Daniel Swift | AK45: Bryan Woodman | AL45: Victoria Pickles | AM45: James Paltser | AN45: Ajay Maharaj | AO45: Kathleen Mullrooney | AP45: Nicolas Santia | AQ45: Brian Ihnacak | AR45: Brian Jefferson | AS45: Steve Mastoras | AT45: Mike Taylor | AU45: Louise Pickles | AV45: Andrew MacDonald | AW45: James Asaad | AX45: Rod Akins | AY45: Maureen Mullrooney | AZ45: Connor Lee | BA45: Bill Parkinson
C46: Enzo Fernández | D46: =IFERROR(VLOOKUP($C46,'World Cup Players'!B:X,3,FALSE),0) -> ar Argentina | F46: =IFERROR(VLOOKUP($C46,'World Cup Players'!B:X,9,FALSE),0) -> 570 | G46: =IFERROR(VLOOKUP($C46,'World Cup Players'!B:X,11,FALSE),0) -> 2 | H46: =IFERROR(VLOOKUP($C46,'World Cup Players'!B:X,12,FALSE),0) -> 0 | I46: =IFERROR(VLOOKUP($C46,'GAME WINNING GOALS'!A:B,2,FALSE),0) -> 1 | J46: =IFERROR(VLOOKUP($C46,'World Cup Players'!B:X,17,FALSE),0) -> 0 | K46: =IFERROR(VLOOKUP($C46,'World Cup Players'!B:X,18,FALSE),0) -> 0 | L46: =IFERROR(VLOOKUP($C46,'World Cup GK'!B:AE,16,FALSE),0) -> 0 | M46: =IFERROR(VLOOKUP($C46,'World Cup GK'!B:AE,19,FALSE),0) -> 0 | N46: =IFERROR(VLOOKUP($C46,'World Cup GK'!B:AE,14,FALSE),0) -> 0 | O46: =IFERROR(VLOOKUP($C46,'World Cup GK'!B:AE,11,FALSE),0) -> 0 | P46: =SUM((F46*0.0083)+G46+H46+I46+L46+M46+(N46*0.2))-((J46*0.25)+(K46*0.5))-(O46*0.25) -> 7.731 | T46: =RANK(X46,$X$5:$X$44) -> #N/A | V46: =VLOOKUP(U46,$B$4:$P$1245,15,FALSE) -> #N/A | W46: =0.000000001+W45 -> 5.1e-08 | X46: =V46+W46 -> #N/A
C47: Michael Olise | D47: =IFERROR(VLOOKUP($C47,'World Cup Players'!B:X,3,FALSE),0) -> fr France | F47: =IFERROR(VLOOKUP($C47,'World Cup Players'!B:X,9,FALSE),0) -> 556 | G47: =IFERROR(VLOOKUP($C47,'World Cup Players'!B:X,11,FALSE),0) -> 0 | H47: =IFERROR(VLOOKUP($C47,'World Cup Players'!B:X,12,FALSE),0) -> 5 | I47: =IFERROR(VLOOKUP($C47,'GAME WINNING GOALS'!A:B,2,FALSE),0) -> 0 | J47: =IFERROR(VLOOKUP($C47,'World Cup Players'!B:X,17,FALSE),0) -> 1 | K47: =IFERROR(VLOOKUP($C47,'World Cup Players'!B:X,18,FALSE),0) -> 0 | L47: =IFERROR(VLOOKUP($C47,'World Cup GK'!B:AE,16,FALSE),0) -> 0 | M47: =IFERROR(VLOOKUP($C47,'World Cup GK'!B:AE,19,FALSE),0) -> 0 | N47: =IFERROR(VLOOKUP($C47,'World Cup GK'!B:AE,14,FALSE),0) -> 0 | O47: =IFERROR(VLOOKUP($C47,'World Cup GK'!B:AE,11,FALSE),0) -> 0 | P47: =SUM((F47*0.0083)+G47+H47+I47+L47+M47+(N47*0.2))-((J47*0.25)+(K47*0.5))-(O47*0.25) -> 9.3648 | V47: =VLOOKUP(U47,$B$4:$P$1245,15,FALSE) -> #N/A | W47: =0.000000001+W46 -> 5.2e-08 | X47: =V47+W47 -> #N/A
C48: Nico Williams | D48: =IFERROR(VLOOKUP($C48,'World Cup Players'!B:X,3,FALSE),0) -> es Spain | F48: =IFERROR(VLOOKUP($C48,'World Cup Players'!B:X,9,FALSE),0) -> 67 | G48: =IFERROR(VLOOKUP($C48,'World Cup Players'!B:X,11,FALSE),0) -> 0 | H48: =IFERROR(VLOOKUP($C48,'World Cup Players'!B:X,12,FALSE),0) -> 0 | I48: =IFERROR(VLOOKUP($C48,'GAME WINNING GOALS'!A:B,2,FALSE),0) -> 0 | J48: =IFERROR(VLOOKUP($C48,'World Cup Players'!B:X,17,FALSE),0) -> 0 | K48: =IFERROR(VLOOKUP($C48,'World Cup Players'!B:X,18,FALSE),0) -> 0 | L48: =IFERROR(VLOOKUP($C48,'World Cup GK'!B:AE,16,FALSE),0) -> 0 | M48: =IFERROR(VLOOKUP($C48,'World Cup GK'!B:AE,19,FALSE),0) -> 0 | N48: =IFERROR(VLOOKUP($C48,'World Cup GK'!B:AE,14,FALSE),0) -> 0 | O48: =IFERROR(VLOOKUP($C48,'World Cup GK'!B:AE,11,FALSE),0) -> 0 | P48: =SUM((F48*0.0083)+G48+H48+I48+L48+M48+(N48*0.2))-((J48*0.25)+(K48*0.5))-(O48*0.25) -> 0.5561
C49: Granit Xhaka | D49: =IFERROR(VLOOKUP($C49,'World Cup Players'!B:X,3,FALSE),0) -> ch Switzerland | F49: =IFERROR(VLOOKUP($C49,'World Cup Players'!B:X,9,FALSE),0) -> 600 | G49: =IFERROR(VLOOKUP($C49,'World Cup Players'!B:X,11,FALSE),0) -> 1 | H49: =IFERROR(VLOOKUP($C49,'World Cup Players'!B:X,12,FALSE),0) -> 0 | I49: =IFERROR(VLOOKUP($C49,'GAME WINNING GOALS'!A:B,2,FALSE),0) -> 0 | J49: =IFERROR(VLOOKUP($C49,'World Cup Players'!B:X,17,FALSE),0) -> 2 | K49: =IFERROR(VLOOKUP($C49,'World Cup Players'!B:X,18,FALSE),0) -> 0 | L49: =IFERROR(VLOOKUP($C49,'World Cup GK'!B:AE,16,FALSE),0) -> 0 | M49: =IFERROR(VLOOKUP($C49,'World Cup GK'!B:AE,19,FALSE),0) -> 0 | N49: =IFERROR(VLOOKUP($C49,'World Cup GK'!B:AE,14,FALSE),0) -> 0 | O49: =IFERROR(VLOOKUP($C49,'World Cup GK'!B:AE,11,FALSE),0) -> 0 | P49: =SUM((F49*0.0083)+G49+H49+I49+L49+M49+(N49*0.2))-((J49*0.25)+(K49*0.5))-(O49*0.25) -> 5.48
C50: Ellyes Skhiri | D50: =IFERROR(VLOOKUP($C50,'World Cup Players'!B:X,3,FALSE),0) -> tn Tunisia | F50: =IFERROR(VLOOKUP($C50,'World Cup Players'!B:X,9,FALSE),0) -> 250 | G50: =IFERROR(VLOOKUP($C50,'World Cup Players'!B:X,11,FALSE),0) -> 0 | H50: =IFERROR(VLOOKUP($C50,'World Cup Players'!B:X,12,FALSE),0) -> 0 | I50: =IFERROR(VLOOKUP($C50,'GAME WINNING GOALS'!A:B,2,FALSE),0) -> 0 | J50: =IFERROR(VLOOKUP($C50,'World Cup Players'!B:X,17,FALSE),0) -> 0 | K50: =IFERROR(VLOOKUP($C50,'World Cup Players'!B:X,18,FALSE),0) -> 0 | L50: =IFERROR(VLOOKUP($C50,'World Cup GK'!B:AE,16,FALSE),0) -> 0 | M50: =IFERROR(VLOOKUP($C50,'World Cup GK'!B:AE,19,FALSE),0) -> 0 | N50: =IFERROR(VLOOKUP($C50,'World Cup GK'!B:AE,14,FALSE),0) -> 0 | O50: =IFERROR(VLOOKUP($C50,'World Cup GK'!B:AE,11,FALSE),0) -> 0 | P50: =SUM((F50*0.0083)+G50+H50+I50+L50+M50+(N50*0.2))-((J50*0.25)+(K50*0.5))-(O50*0.25) -> 2.075
...

Sheet World Cup Players
A1: Playing Time | E1: Performance | M1: Per 90 Minutes
H2: Playing Time | L2: Performance | T2: Per 90 Minutes
A3: Rk | B3: Player | C3: Pos | D3: Squad | E3: Age | F3: Club | G3: Born | H3: MP | I3: Starts | J3: Min | K3: 90s | L3: Gls | M3: Ast | N3: G+A | O3: G-PK | P3: PK | Q3: PKatt | R3: CrdY | S3: CrdR | T3: Gls | U3: Ast | V3: G+A | W3: G-PK | X3: G+A-PK | Y3: Matches
A4: 1 | B4: Brenden Aaronson | C4: MF | D4: us United States | E4: 25-267 | F4: 1.eng Leeds United | G4: 2000 | H4: 1 | I4: 1 | J4: 76 | K4: 0.8 | L4: 0 | M4: 0 | N4: 0 | O4: 0 | P4: 0 | Q4: 0 | R4: 0 | S4: 0 | T4: 0 | U4: 0 | V4: 0 | W4: 0 | X4: 0 | Y4: Matches
A5: 2 | B5: Thelo Aasgaard | C5: MF | D5: no Norway | E5: 24-075 | F5: 1.sct Rangers | G5: 2002 | H5: 1 | I5: 1 | J5: 90 | K5: 1 | L5: 1 | M5: 0 | N5: 1 | O5: 1 | P5: 0 | Q5: 0 | R5: 0 | S5: 0 | T5: 1 | U5: 0 | V5: 1 | W5: 1 | X5: 1 | Y5: Matches
A6: 3 | B6: Hamza Abdelkarim | C6: FW | D6: eg Egypt | E6: 18-196 | F6: 4.es Barcelona B | G6: 2008 | H6: 4 | I6: 0 | J6: 60 | K6: 0.7 | L6: 0 | M6: 0 | N6: 0 | O6: 0 | P6: 0 | Q6: 0 | R6: 0 | S6: 0 | T6: 0 | U6: 0 | V6: 0 | W6: 0 | X6: 0 | Y6: Matches
A7: 4 | B7: Hossam Abdelmaguid | C7: DF | D7: eg Egypt | E7: 25-077 | F7: 1.eg Zamalek SC | G7: 2001 | H7: 2 | I7: 0 | J7: 59 | K7: 0.7 | L7: 0 | M7: 0 | N7: 0 | O7: 0 | P7: 0 | Q7: 0 | R7: 0 | S7: 0 | T7: 0 | U7: 0 | V7: 0 | W7: 0 | X7: 0 | Y7: Matches
A8: 5 | B8: Mohamed Abdelmonem | C8: DF | D8: eg Egypt | E8: 27-165 | F8: 1.fr Nice | G8: 1999 | H8: 2 | I8: 1 | J8: 14 | K8: 0.2 | L8: 0 | M8: 0 | N8: 0 | O8: 0 | P8: 0 | Q8: 0 | R8: 0 | S8: 0 | T8: 0 | U8: 0 | V8: 0 | W8: 0 | X8: 0 | Y8: Matches
A9: 6 | B9: Ali Abdi | C9: DF | D9: tn Tunisia | E9: 32-208 | F9: 1.fr Nice | G9: 1993 | H9: 3 | I9: 3 | J9: 269 | K9: 3 | L9: 0 | M9: 0 | N9: 0 | O9: 0 | P9: 0 | Q9: 0 | R9: 0 | S9: 0 | T9: 0 | U9: 0 | V9: 0 | W9: 0 | X9: 0 | Y9: Matches
A10: 7 | B10: Saud Abdulhamid | C10: DF | D10: sa Saudi Arabia | E10: 26-363 | F10: 1.fr Lens | G10: 1999 | H10: 3 | I10: 3 | J10: 269 | K10: 3 | L10: 0 | M10: 0 | N10: 0 | O10: 0 | P10: 0 | Q10: 0 | R10: 1 | S10: 0 | T10: 0 | U10: 0 | V10: 0 | W10: 0 | X10: 0 | Y10: Matches
A11: 8 | B11: Abdulla Abdullaev | C11: DF | D11: uz Uzbekistan | E11: 28-318 | F11: 1.ae Dibba Al Fujairah | G11: 1997 | H11: 2 | I11: 2 | J11: 180 | K11: 2 | L11: 0 | M11: 0 | N11: 0 | O11: 0 | P11: 0 | Q11: 0 | R11: 0 | S11: 0 | T11: 0 | U11: 0 | V11: 0 | W11: 0 | X11: 0 | Y11: Matches
A12: 9 | B12: Yusuf Abdurisag | C12: FW | D12: qa Qatar | E12: 26-344 | F12: 1.qa Al-Wakrah | G12: 1999 | H12: 2 | I12: 2 | J12: 98 | K12: 1.1 | L12: 0 | M12: 0 | N12: 0 | O12: 0 | P12: 0 | Q12: 0 | R12: 0 | S12: 0 | T12: 0 | U12: 0 | V12: 0 | W12: 0 | X12: 0 | Y12: Matches
A13: 10 | B13: Husam Abu Dahab | C13: DF | D13: jo Jordan | E13: 26-064 | F13: 1.kw Al-Salmiya SC | G13: 2000 | H13: 2 | I13: 2 | J13: 178 | K13: 2 | L13: 0 | M13: 0 | N13: 0 | O13: 0 | P13: 0 | Q13: 0 | R13: 1 | S13: 0 | T13: 0 | U13: 0 | V13: 0 | W13: 0 | X13: 0 | Y13: Matches
A14: 11 | B14: Mohammad Abu Hasheesh | C14: DF | D14: jo Jordan | E14: 31-068 | F14: 1.iq Al-Karma | G14: 1995 | H14: 1 | I14: 0 | J14: 6 | K14: 0.1 | L14: 0 | M14: 0 | N14: 0 | O14: 0 | P14: 0 | Q14: 0 | R14: 0 | S14: 0 | T14: 0 | U14: 0 | V14: 0 | W14: 0 | X14: 0 | Y14: Matches
A15: 12 | B15: Mohannad Abu Taha | C15: DF | D15: jo Jordan | E15: 23-164 | F15: 1.iq Al-Quwa Al-Jawiya | G15: 2003 | H15: 3 | I15: 3 | J15: 264 | K15: 2.9 | L15: 0 | M15: 0 | N15: 0 | O15: 0 | P15: 0 | Q15: 0 | R15: 1 | S15: 0 | T15: 0 | U15: 0 | V15: 0 | W15: 0 | X15: 0 | Y15: Matches
... A28: 25 | B28: Akram Afif | C28: FW,MF | D28: qa Qatar | E28: 29-240 | F28: 1.qa Al Sadd | G28: 1996 | H28: 3 | I28: 3 | J28: 238 | K28: 2.6 | L28: 0 | M28: 0 | N28: 0 | O28: 0 | P28: 0 | Q28: 0 | R28: 0 | S28: 0 | T28: 0 | U28: 0 | V28: 0 | W28: 0 | X28: 0 | Y28: Matches
A29: Rk | B29: Player | C29: Pos | D29: Squad | E29: Age | F29: Club | G29: Born | H29: MP | I29: Starts | J29: Min | K29: 90s | L29: Gls | M29: Ast | N29: G+A | O29: G-PK | P29: PK | Q29: PKatt | R29: CrdY | S29: CrdR | T29: Gls | U29: Ast | V29: G+A | W29: G-PK | X29: G+A-PK | Y29: Matches
A30: 26 | B30: Emmanuel Agbadou | C30: DF | D30: ci Côte d'Ivoire | E30: 29-029 | F30: 1.tr Beşiktaş | G30: 1997 | H30: 3 | I30: 3 | J30: 270 | K30: 3 | L30: 0 | M30: 0 | N30: 0 | O30: 0 | P30: 0 | Q30: 0 | R30: 0 | S30: 0 | T30: 0 | U30: 0 | V30: 0 | W30: 0 | X30: 0 | Y30: Matches
A31: 27 | B31: Rodrigo Aguirre | C31: FW | D31: uy Uruguay | E31: 31-288 | F31: 1.mx América | G31: 1994 | H31: 1 | I31: 0 | J31: 1 | K31: 0 | L31: 0 | M31: 0 | N31: 0 | O31: 0 | P31: 0 | Q31: 0 | R31: 0 | S31: 0 | T31: 0 | U31: 0 | V31: 0 | W31: 0 | X31: 0 | Y31: Matches
A32: 28 | B32: Ali Ahmed | C32: MF | D32: ca Canada | E32: 25-279 | F32: 2.eng Norwich City | G32: 2000 | H32: 4 | I32: 3 | J32: 234 | K32: 2.6 | L32: 0 | M32: 0 | N32: 0 | O32: 0 | P32: 0 | Q32: 0 | R32: 0 | S32: 0 | T32: 0 | U32: 0 | V32: 0 | W32: 0 | X32: 0 | Y32: Matches
A33: 29 | B33: Homam Ahmed | C33: DF | D33: qa Qatar | E33: 26-325 | F33: 2.es Cultural Leonesa | G33: 1999 | H33: 2 | I33: 2 | J33: 122 | K33: 1.4 | L33: 0 | M33: 1 | N33: 1 | O33: 0 | P33: 0 | Q33: 0 | R33: 0 | S33: 1 | T33: 0 | U33: 0.74 | V33: 0.74 | W33: 0 | X33: 0.74 | Y33: Matches
A34: 30 | B34: Rayan Aït-Nouri | C34: DF | D34: dz Algeria | E34: 25-040 | F34: 1.eng Manchester City | G34: 2001 | H34: 4 | I34: 3 | J34: 284 | K34: 3.2 | L34: 0 | M34: 0 | N34: 0 | O34: 0 | P34: 0 | Q34: 0 | R34: 0 | S34: 0 | T34: 0 | U34: 0 | V34: 0 | W34: 0 | X34: 0 | Y34: Matches
A35: 31 | B35: Kristoffer Ajer | C35: DF | D35: no Norway | E35: 28-090 | F35: 1.eng Brentford | G35: 1998 | H35: 5 | I35: 5 | J35: 480 | K35: 5.3 | L35: 0 | M35: 0 | N35: 0 | O35: 0 | P35: 0 | Q35: 0 | R35: 1 | S35: 0 | T35: 0 | U35: 0 | V35: 0 | W35: 0 | X35: 0 | Y35: Matches
A36: 32 | B36: Manuel Akanji | C36: DF | D36: ch Switzerland | E36: 30-362 | F36: 1.it Inter | G36: 1995 | H36: 6 | I36: 6 | J36: 600 | K36: 6.7 | L36: 0 | M36: 0 | N36: 0 | O36: 0 | P36: 0 | Q36: 0 | R36: 0 | S36: 0 | T36: 0 | U36: 0 | V36: 0 | W36: 0 | X36: 0 | Y36: Matches
A37: 33 | B37: Nathan Aké | C37: DF | D37: nl Netherlands | E37: 31-148 | F37: 1.eng Manchester City | G37: 1995 | H37: 3 | I37: 2 | J37: 170 | K37: 1.9 | L37: 0 | M37: 0 | N37: 0 | O37: 0 | P37: 0 | Q37: 0 | R37: 0 | S37: 0 | T37: 0 | U37: 0 | V37: 0 | W37: 0 | X37: 0 | Y37: Matches
A38: 34 | B38: Yunus Akgün | C38: MF | D38: tr Türkiye | E38: 26-009 | F38: 1.tr Galatasaray | G38: 2000 | H38: 2 | I38: 1 | J38: 88 | K38: 1 | L38: 0 | M38: 0 | N38: 0 | O38: 0 | P38: 0 | Q38: 0 | R38: 1 | S38: 0 | T38: 0 | U38: 0 | V38: 0 | W38: 0 | X38: 0 | Y38: Matches
A39: 35 | B39: Maghnes Akliouche | C39: MF | D39: fr France | E39: 24-141 | F39: 1.fr Monaco | G39: 2002 | H39: 1 | I39: 0 | J39: 8 | K39: 0.1 | L39: 0 | M39: 0 | N39: 0 | O39: 0 | P39: 0 | Q39: 0 | R39: 0 | S39: 0 | T39: 0 | U39: 0 | V39: 0 | W39: 0 | X39: 0 | Y39: Matches
A40: 36 | B40: Kerem Aktürkoğlu | C40: FW | D40: tr Türkiye | E40: 27-268 | F40: 1.tr Fenerbahçe | G40: 1998 | H40: 2 | I40: 2 | J40: 129 | K40: 1.4 | L40: 0 | M40: 0 | N40: 0 | O40: 0 | P40: 0 | Q40: 0 | R40: 0 | S40: 0 | T40: 0 | U40: 0 | V40: 0 | W40: 0 | X40: 0 | Y40: Matches
A41: 37 | B41: Ahmed Alaaeldin | C41: FW | D41: qa Qatar | E41: 33-166 | F41: 1.qa Al Rayyan SC | G41: 1993 | H41: 2 | I41: 0 | J41: 43 | K41: 0.5 | L41: 0 | M41: 0 | N41: 0 | O41: 0 | P41: 0 | Q41: 0 | R41: 0 | S41: 0 | T41: 0 | U41: 0 | V41: 0 | W41: 0 | X41: 0 | Y41: Matches
... A54: 50 | B54: Miguel Almirón | C54: MF,FW | D54: py Paraguay | E54: 32-156 | F54: 1.us Atlanta Utd | G54: 1994 | H54: 4 | I54: 4 | J54: 282 | K54: 3.1 | L54: 0 | M54: 0 | N54: 0 | O54: 0 | P54: 0 | Q54: 0 | R54: 1 | S54: 1 | T54: 0 | U54: 0 | V54: 0 | W54: 0 | X54: 0 | Y54: Matches
A55: Rk | B55: Player | C55: Pos | D55: Squad | E55: Age | F55: Club | G55: Born | H55: MP | I55: Starts | J55: Min | K55: 90s | L55: Gls | M55: Ast | N55: G+A | O55: G-PK | P55: PK | Q55: PKatt | R55: CrdY | S55: CrdR | T55: Gls | U55: Ast | V55: G+A | W55: G-PK | X55: G+A-PK | Y55: Matches
A56: 51 | B56: Júnior Alonso | C56: DF | D56: py Paraguay | E56: 33-157 | F56: 1.br Atlético Mineiro | G56: 1993 | H56: 5 | I56: 4 | J56: 390 | K56: 4.3 | L56: 0 | M56: 0 | N56: 0 | O56: 0 | P56: 0 | Q56: 0 | R56: 1 | S56: 0 | T56: 0 | U56: 0 | V56: 0 | W56: 0 | X56: 0 | Y56: Matches
A57: 52 | B57: Barış Alper Yılmaz | C57: MF,FW | D57: tr Türkiye | E57: 26-054 | F57: 1.tr Galatasaray | G57: 2000 | H57: 3 | I57: 2 | J57: 179 | K57: 2 | L57: 1 | M57: 1 | N57: 2 | O57: 1 | P57: 0 | Q57: 0 | R57: 0 | S57: 0 | T57: 0.5 | U57: 0.5 | V57: 1.01 | W57: 0.5 | X57: 1.01 | Y57: Matches
A58: 53 | B58: Roberto Alvarado | C58: FW,MF | D58: mx Mexico | E58: 27-312 | F58: 1.mx Guadalajara | G58: 1998 | H58: 5 | I58: 5 | J58: 428 | K58: 4.8 | L58: 0 | M58: 3 | N58: 3 | O58: 0 | P58: 0 | Q58: 0 | R58: 0 | S58: 0 | T58: 0 | U58: 0.63 | V58: 0.63 | W58: 0 | X58: 0.63 | Y58: Matches
A59: 54 | B59: Edson Álvarez | C59: MF,DF | D59: mx Mexico | E59: 28-265 | F59: 1.eng West Ham | G59: 1997 | H59: 4 | I59: 2 | J59: 240 | K59: 2.7 | L59: 0 | M59: 0 | N59: 0 | O59: 0 | P59: 0 | Q59: 0 | R59: 1 | S59: 0 | T59: 0 | U59: 0 | V59: 0 | W59: 0 | X59: 0 | Y59: Matches
A60: 55 | B60: Julián Álvarez | C60: FW | D60: ar Argentina | E60: 26-166 | F60: 1.es Atlético Madrid | G60: 2000 | H60: 7 | I60: 4 | J60: 501 | K60: 5.6 | L60: 1 | M60: 0 | N60: 1 | O60: 1 | P60: 0 | Q60: 0 | R60: 0 | S60: 0 | T60: 0.18 | U60: 0 | V60: 0.18 | W60: 0.18 | X60: 0.18 | Y60: Matches
A61: 56 | B61: Ayoube Amaimouni | C61: MF | D61: ma Morocco | E61: 21-228 | F61: 1.de Frankfurt | G61: 2004 | H61: 2 | I61: 0 | J61: 18 | K61: 0.2 | L61: 0 | M61: 0 | N61: 0 | O61: 0 | P61: 0 | Q61: 0 | R61: 0 | S61: 0 | T61: 0 | U61: 0 | V61: 0 | W61: 0 | X61: 0 | Y61: Matches
A62: 57 | B62: Zeki Amdouni | C62: FW,MF | D62: ch Switzerland | E62: 25-224 | F62: 1.eng Burnley | G62: 2000 | H62: 4 | I62: 0 | J62: 73 | K62: 0.8 | L62: 0 | M62: 0 | N62: 0 | O62: 0 | P62: 0 | Q62: 0 | R62: 0 | S62: 0 | T62: 0 | U62: 0 | V62: 0 | W62: 0 | X62: 0 | Y62: Matches
A63: 58 | B63: Michael Amir Murillo | C63: DF,MF | D63: pa Panama | E63: 30-155 | F63: 1.tr Beşiktaş | G63: 1996 | H63: 3 | I63: 3 | J63: 270 | K63: 3 | L63: 0 | M63: 0 | N63: 0 | O63: 0 | P63: 0 | Q63: 0 | R63: 0 | S63: 0 | T63: 0 | U63: 0 | V63: 0 | W63: 0 | X63: 0 | Y63: Matches
A64: 59 | B64: Nadiem Amiri | C64: MF | D64: de Germany | E64: 29-262 | F64: 1.de Mainz 05 | G64: 1996 | H64: 2 | I64: 0 | J64: 42 | K64: 0.5 | L64: 0 | M64: 1 | N64: 1 | O64: 0 | P64: 0 | Q64: 0 | R64: 0 | S64: 0 | T64: 0 | U64: 2.14 | V64: 2.14 | W64: 0 | X64: 2.14 | Y64: Matches
...

Sheet World Cup GK
A1: Playing Time | E1: Performance | O1: Penalty Kicks
A2: Rk | B2: Player | C2: Pos | D2: Squad | E2: Age | F2: Club | G2: Born | H2: MP | I2: Starts | J2: Min | K2: 90s | L2: GA | M2: GA90 | N2: SoTA | O2: Saves | P2: Save% | Q2: W | R2: D | S2: L | T2: CS | U2: CS% | V2: PKatt | W2: PKA | X2: PKsv | Y2: PKm | Z2: Save% | AA2: Matches
A3: 1 | B3: Yazeed Abulaila | C3: GK | D3: jo Jordan | E3: 33-189 | F3: 1.jo Al-Hussein SC | G3: 1993 | H3: 3 | I3: 3 | J3: 270 | K3: 3 | L3: 8 | M3: 2.67 | N3: 16 | O3: 8 | P3: 50 | Q3: 0 | R3: 0 | S3: 3 | T3: 0 | U3: 0 | V3: 2 | W3: 2 | X3: 0 | Y3: 0 | Z3: 0 | AA3: Matches
A4: 2 | B4: Mahmoud Abunada | C4: GK | D4: qa Qatar | E4: 26-161 | F4: 1.qa Al Rayyan SC | G4: 2000 | H4: 3 | I4: 3 | J4: 270 | K4: 3 | L4: 10 | M4: 3.33 | N4: 22 | O4: 12 | P4: 54.5 | Q4: 0 | R4: 1 | S4: 2 | T4: 0 | U4: 0 | V4: 1 | W4: 1 | X4: 0 | Y4: 0 | Z4: 0 | AA4: Matches
A5: 3 | B5: Alisson | C5: GK | D5: br Brazil | E5: 33-287 | F5: 1.eng Liverpool | G5: 1992 | H5: 5 | I5: 5 | J5: 450 | K5: 5 | L5: 4 | M5: 0.8 | N5: 18 | O5: 14 | P5: 77.8 | Q5: 3 | R5: 1 | S5: 1 | T5: 2 | U5: 40 | V5: 0 | W5: 0 | X5: 0 | Y5: 0 | AA5: Matches
A6: 4 | B6: Benjamin Asare | C6: GK | D6: gh Ghana | E6: 34-003 | F6: 1.gh Accra Hearts of Oak | G6: 1992 | H6: 3 | I6: 2 | J6: 225 | K6: 2.5 | L6: 2 | M6: 0.8 | N6: 10 | O6: 8 | P6: 80 | Q6: 0 | R6: 1 | S6: 1 | T6: 2 | U6: 100 | V6: 0 | W6: 0 | X6: 0 | Y6: 0 | AA6: Matches
A7: 5 | B7: Lawrence Ati-Zigi | C7: GK | D7: gh Ghana | E7: 29-229 | F7: 1.ch St. Gallen | G7: 1996 | H7: 2 | I7: 2 | J7: 135 | K7: 1.5 | L7: 1 | M7: 0.67 | N7: 9 | O7: 8 | P7: 88.9 | Q7: 1 | R7: 0 | S7: 1 | T7: 1 | U7: 50 | V7: 0 | W7: 0 | X7: 0 | Y7: 0 | AA7: Matches
A8: 6 | B8: Ahmed Basil | C8: GK | D8: iq Iraq | E8: 29-331 | F8: 1.iq Al-Shorta | G8: 1996 | H8: 2 | I8: 2 | J8: 135 | K8: 1.5 | L8: 4 | M8: 2.67 | N8: 7 | O8: 3 | P8: 42.9 | Q8: 0 | R8: 0 | S8: 2 | T8: 0 | U8: 0 | V8: 0 | W8: 0 | X8: 0 | Y8: 0 | AA8: Matches
A9: 7 | B9: Patrick Beach | C9: GK | D9: au Australia | E9: 22-344 | F9: 1.au Melb City | G9: 2003 | H9: 4 | I9: 4 | J9: 388 | K9: 4.3 | L9: 3 | M9: 0.7 | N9: 17 | O9: 14 | P9: 82.4 | Q9: 1 | R9: 2 | S9: 1 | T9: 2 | U9: 50 | V9: 0 | W9: 0 | X9: 0 | Y9: 0 | AA9: Matches
A10: 8 | B10: Alireza Beiranvand | C10: GK | D10: ir IR Iran | E10: 33-298 | F10: 1.ir Tractor | G10: 1992 | H10: 3 | I10: 3 | J10: 270 | K10: 3 | L10: 3 | M10: 1 | N10: 18 | O10: 15 | P10: 83.3 | Q10: 0 | R10: 3 | S10: 0 | T10: 1 | U10: 33.3 | V10: 0 | W10: 0 | X10: 0 | Y10: 0 | AA10: Matches
